/**
 * Comprehensive Error Recovery and User-Facing Error Display Tests
 * Tests error recovery mechanisms, retry logic, fallbacks, and user-friendly error messages
 */

import { setTimeout } from 'timers/promises';

// Mock error recovery utilities
const mockErrorRecovery = {
  retryWithBackoff: jest.fn(),
  fallbackToCache: jest.fn(),
  gracefulDegradation: jest.fn(),
  notifyUser: jest.fn(),
  logError: jest.fn(),
  reportErrorMetrics: jest.fn(),
};

// Mock cache for fallback scenarios
const mockCache = {
  get: jest.fn(),
  set: jest.fn(),
  has: jest.fn(),
  delete: jest.fn(),
};

// Mock user notification system
const mockNotification = {
  showError: jest.fn(),
  showWarning: jest.fn(),
  showSuccess: jest.fn(),
  showRetrying: jest.fn(),
  showFallback: jest.fn(),
};

// Mock service clients
const mockServiceClients = {
  primary: { makeRequest: jest.fn() },
  fallback: { makeRequest: jest.fn() },
  cache: mockCache,
};

// Circuit breaker implementation mock
class MockCircuitBreaker {
  private state: 'CLOSED' | 'OPEN' | 'HALF_OPEN' = 'CLOSED';
  private failureCount = 0;
  private failureThreshold = 5;
  private timeout = 60000; // 1 minute
  private nextAttempt = 0;

  async execute<T>(fn: () => Promise<T>): Promise<T> {
    if (this.state === 'OPEN') {
      if (Date.now() < this.nextAttempt) {
        throw new Error('Circuit breaker is OPEN');
      }
      this.state = 'HALF_OPEN';
    }

    try {
      const result = await fn();
      this.onSuccess();
      return result;
    } catch (error) {
      this.onFailure();
      throw error;
    }
  }

  private onSuccess() {
    this.failureCount = 0;
    this.state = 'CLOSED';
  }

  private onFailure() {
    this.failureCount++;
    if (this.failureCount >= this.failureThreshold) {
      this.state = 'OPEN';
      this.nextAttempt = Date.now() + this.timeout;
    }
  }

  getState() {
    return this.state;
  }

  getFailureCount() {
    return this.failureCount;
  }
}

describe('Error Recovery and User Experience Scenarios', () => {
  beforeEach(() => {
    jest.clearAllMocks();
  });

  describe('Retry Mechanisms', () => {
    it('should implement exponential backoff retry', async () => {
      const attempts: number[] = [];
      let attemptCount = 0;

      mockErrorRecovery.retryWithBackoff.mockImplementation(async (fn, options = {}) => {
        const maxAttempts = options.maxAttempts || 3;
        const baseDelay = options.baseDelay || 1000;
        const maxDelay = options.maxDelay || 10000;

        while (attemptCount < maxAttempts) {
          try {
            attemptCount++;
            const delay = Math.min(baseDelay * Math.pow(2, attemptCount - 1), maxDelay);
            attempts.push(delay);
            
            if (attemptCount < maxAttempts) {
              await setTimeout(1); // Fast test execution
            }
            
            return await fn();
          } catch (error) {
            if (attemptCount >= maxAttempts) {
              throw new Error(`Max attempts (${maxAttempts}) exceeded. Last error: ${(error as Error).message}`);
            }
          }
        }
      });

      const failingFunction = jest.fn()
        .mockRejectedValueOnce(new Error('Attempt 1 failed'))
        .mockRejectedValueOnce(new Error('Attempt 2 failed'))
        .mockResolvedValueOnce('Success on attempt 3');

      const result = await mockErrorRecovery.retryWithBackoff(
        failingFunction,
        { maxAttempts: 3, baseDelay: 100 }
      );

      expect(result).toBe('Success on attempt 3');
      expect(attemptCount).toBe(3);
      expect(attempts).toHaveLength(3);
      expect(attempts[0]).toBe(100);  // 100 * 2^0
      expect(attempts[1]).toBe(200);  // 100 * 2^1
      expect(attempts[2]).toBe(400);  // 100 * 2^2
    });

    it('should handle retry with jitter', async () => {
      const retryWithJitter = async (fn: () => Promise<any>, options: any = {}) => {
        const maxAttempts = options.maxAttempts || 3;
        const baseDelay = options.baseDelay || 1000;
        const jitterFactor = options.jitterFactor || 0.1;
        
        let attempts = 0;
        const delays: number[] = [];

        while (attempts < maxAttempts) {
          try {
            attempts++;
            return await fn();
          } catch (error) {
            if (attempts >= maxAttempts) throw error;
            
            const exponentialDelay = baseDelay * Math.pow(2, attempts - 1);
            const jitter = Math.random() * jitterFactor * exponentialDelay;
            const finalDelay = exponentialDelay + jitter;
            delays.push(finalDelay);
            
            await setTimeout(1); // Fast test execution
          }
        }
        return delays;
      };

      const failingFunction = jest.fn()
        .mockRejectedValueOnce(new Error('Fail 1'))
        .mockRejectedValueOnce(new Error('Fail 2'))
        .mockResolvedValueOnce('Success');

      await retryWithJitter(failingFunction, {
        maxAttempts: 3,
        baseDelay: 1000,
        jitterFactor: 0.1
      });

      expect(failingFunction).toHaveBeenCalledTimes(3);
    });

    it('should implement intelligent retry based on error type', async () => {
      const shouldRetry = (error: any) => {
        // Retry on temporary failures, not on permanent ones
        if (error.code === 'ECONNRESET' || error.code === 'ETIMEDOUT') return true;
        if (error.status >= 500 && error.status < 600) return true;
        if (error.status === 429) return true; // Rate limit
        if (error.status === 408) return true; // Request timeout
        return false;
      };

      const intelligentRetry = async (fn: () => Promise<any>, maxAttempts = 3) => {
        let attempts = 0;
        while (attempts < maxAttempts) {
          try {
            attempts++;
            return await fn();
          } catch (error) {
            const shouldRetryError = shouldRetry(error);
            
            if (!shouldRetryError || attempts >= maxAttempts) {
              throw new Error(`Non-retryable error or max attempts exceeded: ${(error as Error).message}`);
            }
            
            await setTimeout(1); // Fast test execution
          }
        }
      };

      // Test retryable error (500 server error)
      const retryableError = { status: 500, message: 'Internal server error' };
      const retryableFunction = jest.fn()
        .mockRejectedValueOnce(retryableError)
        .mockResolvedValueOnce('Success');

      const result1 = await intelligentRetry(retryableFunction);
      expect(result1).toBe('Success');
      expect(retryableFunction).toHaveBeenCalledTimes(2);

      // Test non-retryable error (400 client error)
      const nonRetryableError = { status: 400, message: 'Bad request' };
      const nonRetryableFunction = jest.fn().mockRejectedValue(nonRetryableError);

      await expect(intelligentRetry(nonRetryableFunction)).rejects.toThrow('Non-retryable error');
      expect(nonRetryableFunction).toHaveBeenCalledTimes(1); // Should not retry
    });

    it('should implement timeout-based retry cancellation', async () => {
      const retryWithTimeout = async (fn: () => Promise<any>, options: any = {}) => {
        const totalTimeout = options.totalTimeout || 10000;
        const startTime = Date.now();
        let attempts = 0;

        while (Date.now() - startTime < totalTimeout) {
          try {
            attempts++;
            return await fn();
          } catch (error) {
            if (Date.now() - startTime >= totalTimeout) {
              throw new Error(`Retry timeout exceeded after ${totalTimeout}ms and ${attempts} attempts`);
            }
            await setTimeout(1); // Fast test execution
          }
        }
      };

      const slowFailingFunction = jest.fn().mockRejectedValue(new Error('Always fails'));

      await expect(
        retryWithTimeout(slowFailingFunction, { totalTimeout: 100 })
      ).rejects.toThrow('Retry timeout exceeded');
    });
  });

  describe('Fallback Mechanisms', () => {
    it('should fallback to cached data when service is unavailable', async () => {
      const cachedData = { id: '123', title: 'Cached Campaign', cached: true };
      
      mockCache.has.mockReturnValue(true);
      mockCache.get.mockReturnValue(cachedData);
      
      mockErrorRecovery.fallbackToCache.mockImplementation(async (key, fetchFn) => {
        try {
          return await fetchFn();
        } catch (error) {
          if (mockCache.has(key)) {
            const cachedResult = mockCache.get(key);
            return { ...cachedResult, fromCache: true };
          }
          throw error;
        }
      });

      const failingService = jest.fn().mockRejectedValue(new Error('Service unavailable'));
      
      const result = await mockErrorRecovery.fallbackToCache('campaign:123', failingService);
      
      expect(result).toEqual({ ...cachedData, fromCache: true });
      expect(mockCache.has).toHaveBeenCalledWith('campaign:123');
      expect(mockCache.get).toHaveBeenCalledWith('campaign:123');
    });

    it('should fallback to secondary service when primary fails', async () => {
      mockServiceClients.primary.makeRequest.mockRejectedValue(new Error('Primary service down'));
      mockServiceClients.fallback.makeRequest.mockResolvedValue({ data: 'fallback data' });

      const serviceFallback = async (request: any) => {
        try {
          return await mockServiceClients.primary.makeRequest(request);
        } catch (primaryError) {
          console.warn('Primary service failed, trying fallback:', primaryError.message);
          try {
            const fallbackResult = await mockServiceClients.fallback.makeRequest(request);
            return { ...fallbackResult, usedFallback: true };
          } catch (fallbackError) {
            throw new Error(`Both primary and fallback services failed: ${fallbackError.message}`);
          }
        }
      };

      const result = await serviceFallback({ endpoint: '/data' });
      
      expect(result).toEqual({ data: 'fallback data', usedFallback: true });
      expect(mockServiceClients.primary.makeRequest).toHaveBeenCalled();
      expect(mockServiceClients.fallback.makeRequest).toHaveBeenCalled();
    });

    it('should implement graceful degradation for feature unavailability', async () => {
      mockErrorRecovery.gracefulDegradation.mockImplementation(async (primaryFeature, fallbackFeature) => {
        try {
          return await primaryFeature();
        } catch (error) {
          console.warn('Primary feature unavailable, using fallback:', error.message);
          return await fallbackFeature();
        }
      });

      const primaryFeature = jest.fn().mockRejectedValue(new Error('AI service unavailable'));
      const fallbackFeature = jest.fn().mockResolvedValue({ 
        type: 'fallback',
        message: 'AI-generated content temporarily unavailable. Using template.' 
      });

      const result = await mockErrorRecovery.gracefulDegradation(primaryFeature, fallbackFeature);
      
      expect(result.type).toBe('fallback');
      expect(result.message).toContain('temporarily unavailable');
      expect(fallbackFeature).toHaveBeenCalled();
    });

    it('should handle multiple fallback layers', async () => {
      const multiLayerFallback = async (request: any) => {
        const services = [
          mockServiceClients.primary,
          mockServiceClients.fallback,
          { makeRequest: () => mockCache.get(request.cacheKey) }
        ];

        let lastError: Error | null = null;
        
        for (let i = 0; i < services.length; i++) {
          try {
            const result = await services[i].makeRequest(request);
            return { ...result, serviceLevel: i };
          } catch (error) {
            lastError = error as Error;
            console.warn(`Service level ${i} failed:`, error);
          }
        }
        
        throw new Error(`All service levels failed. Last error: ${lastError?.message}`);
      };

      // Setup: primary fails, fallback fails, cache succeeds
      mockServiceClients.primary.makeRequest.mockRejectedValue(new Error('Primary down'));
      mockServiceClients.fallback.makeRequest.mockRejectedValue(new Error('Fallback down'));
      mockCache.get.mockReturnValue({ data: 'cached result' });

      const result = await multiLayerFallback({ cacheKey: 'test-key' });
      
      expect(result).toEqual({ data: 'cached result', serviceLevel: 2 });
    });
  });

  describe('Circuit Breaker Pattern', () => {
    it('should implement circuit breaker for failing services', async () => {
      const circuitBreaker = new MockCircuitBreaker();
      const failingService = jest.fn().mockRejectedValue(new Error('Service failure'));

      // Trigger failures to open circuit
      for (let i = 0; i < 5; i++) {
        try {
          await circuitBreaker.execute(failingService);
        } catch (error) {
          // Expected failures
        }
      }

      expect(circuitBreaker.getState()).toBe('OPEN');
      expect(circuitBreaker.getFailureCount()).toBe(5);

      // Circuit is open, should reject immediately
      await expect(circuitBreaker.execute(failingService)).rejects.toThrow('Circuit breaker is OPEN');
      
      // Service call count should not increase when circuit is open
      expect(failingService).toHaveBeenCalledTimes(5);
    });

    it('should transition from OPEN to HALF_OPEN after timeout', async () => {
      const circuitBreaker = new MockCircuitBreaker();
      const service = jest.fn()
        .mockRejectedValueOnce(new Error('Fail'))
        .mockRejectedValueOnce(new Error('Fail'))
        .mockRejectedValueOnce(new Error('Fail'))
        .mockRejectedValueOnce(new Error('Fail'))
        .mockRejectedValueOnce(new Error('Fail')) // Opens circuit
        .mockResolvedValueOnce('Success'); // Should succeed in HALF_OPEN

      // Trigger failures to open circuit
      for (let i = 0; i < 5; i++) {
        try {
          await circuitBreaker.execute(service);
        } catch (error) {
          // Expected failures
        }
      }

      expect(circuitBreaker.getState()).toBe('OPEN');

      // Simulate timeout passing and successful recovery
      // In real implementation, we'd wait for the actual timeout
      // For testing, we'll modify the internal state simulation
      const result = await circuitBreaker.execute(service);
      
      expect(result).toBe('Success');
      expect(circuitBreaker.getState()).toBe('CLOSED');
      expect(circuitBreaker.getFailureCount()).toBe(0);
    });

    it('should provide circuit breaker metrics', async () => {
      const circuitBreaker = new MockCircuitBreaker();
      const service = jest.fn()
        .mockRejectedValueOnce(new Error('Fail 1'))
        .mockRejectedValueOnce(new Error('Fail 2'))
        .mockResolvedValueOnce('Success');

      // Two failures, then success
      try {
        await circuitBreaker.execute(service);
      } catch (error) {
        // Expected failure
      }
      
      try {
        await circuitBreaker.execute(service);
      } catch (error) {
        // Expected failure
      }
      
      const result = await circuitBreaker.execute(service);
      
      expect(result).toBe('Success');
      expect(circuitBreaker.getState()).toBe('CLOSED');
      expect(circuitBreaker.getFailureCount()).toBe(0);
    });
  });

  describe('User-Facing Error Messages', () => {
    it('should display user-friendly error messages', async () => {
      const errorMessageMap = {
        'ECONNREFUSED': 'Service is temporarily unavailable. Please try again later.',
        'ETIMEDOUT': 'Request timed out. Please check your connection and try again.',
        'ENOTFOUND': 'Unable to connect to the service. Please check your internet connection.',
        'RATE_LIMITED': 'Too many requests. Please wait a moment and try again.',
        'VALIDATION_ERROR': 'Please check your input and try again.',
        'AUTHENTICATION_ERROR': 'Please sign in again to continue.',
        'PERMISSION_ERROR': 'You don\'t have permission to perform this action.',
        'NOT_FOUND': 'The requested item could not be found.',
        'SERVER_ERROR': 'Something went wrong on our end. We\'re working to fix it.'
      };

      mockNotification.showError.mockImplementation((error, userMessage) => {
        return { error, userMessage, timestamp: Date.now() };
      });

      // Test different error types
      const testCases = [
        { code: 'ECONNREFUSED', technical: 'Connection refused' },
        { code: 'ETIMEDOUT', technical: 'Request timeout after 30s' },
        { code: 'ENOTFOUND', technical: 'getaddrinfo ENOTFOUND api.example.com' },
        { code: 'RATE_LIMITED', technical: '429 Too Many Requests' },
        { status: 400, technical: 'Invalid request body' },
        { status: 401, technical: 'Token expired' },
        { status: 403, technical: 'Insufficient permissions' },
        { status: 404, technical: 'Resource not found' },
        { status: 500, technical: 'Internal server error' }
      ];

      const notifications = testCases.map(testCase => {
        const errorCode = testCase.code || 
          (testCase.status === 400 ? 'VALIDATION_ERROR' :
           testCase.status === 401 ? 'AUTHENTICATION_ERROR' :
           testCase.status === 403 ? 'PERMISSION_ERROR' :
           testCase.status === 404 ? 'NOT_FOUND' :
           testCase.status === 500 ? 'SERVER_ERROR' : 'UNKNOWN');
        
        return mockNotification.showError(
          testCase,
          errorMessageMap[errorCode] || 'An unexpected error occurred.'
        );
      });

      notifications.forEach((notification, index) => {
        expect(notification.userMessage).toBeDefined();
        expect(notification.userMessage).not.toContain('ECONNREFUSED');
        expect(notification.userMessage).not.toContain('getaddrinfo');
        expect(notification.userMessage).not.toContain('500');
      });
    });

    it('should provide contextual error messages based on user action', async () => {
      const contextualErrors = {
        'campaign_creation': {
          'VALIDATION_ERROR': 'Please check your campaign details and try again.',
          'UPLOAD_ERROR': 'There was a problem uploading your image. Please try again.',
          'PAYMENT_ERROR': 'We couldn\'t process your payment. Please check your payment method.'
        },
        'pledge_creation': {
          'VALIDATION_ERROR': 'Please enter a valid pledge amount.',
          'PAYMENT_ERROR': 'Your payment could not be processed. Please try a different payment method.',
          'CAMPAIGN_ERROR': 'This campaign is no longer accepting pledges.'
        },
        'user_authentication': {
          'AUTHENTICATION_ERROR': 'Invalid email or password. Please try again.',
          'RATE_LIMITED': 'Too many login attempts. Please wait a few minutes and try again.',
          'ACCOUNT_LOCKED': 'Your account has been temporarily locked for security reasons.'
        }
      };

      const getContextualMessage = (context: string, errorType: string) => {
        return contextualErrors[context]?.[errorType] || 'Something went wrong. Please try again.';
      };

      expect(getContextualMessage('campaign_creation', 'VALIDATION_ERROR'))
        .toBe('Please check your campaign details and try again.');
      
      expect(getContextualMessage('pledge_creation', 'PAYMENT_ERROR'))
        .toBe('Your payment could not be processed. Please try a different payment method.');
      
      expect(getContextualMessage('user_authentication', 'RATE_LIMITED'))
        .toBe('Too many login attempts. Please wait a few minutes and try again.');
    });

    it('should display retry and recovery options', async () => {
      const errorWithRecovery = {
        showRetryOption: (error: any) => {
          const retryableErrors = ['ETIMEDOUT', 'ECONNRESET', 'RATE_LIMITED', 'SERVER_ERROR'];
          return retryableErrors.some(code => 
            error.code === code || 
            (error.status >= 500 && error.status < 600) ||
            error.status === 429
          );
        },
        
        showFallbackOption: (error: any, context: string) => {
          if (context === 'campaign_list' && error.code === 'ECONNREFUSED') {
            return 'Show cached campaigns instead';
          }
          if (context === 'image_upload' && error.type === 'UPLOAD_ERROR') {
            return 'Try uploading a different image';
          }
          return null;
        },
        
        getRecoveryActions: (error: any, context: string) => {
          const actions = [];
          
          if (errorWithRecovery.showRetryOption(error)) {
            actions.push({ type: 'retry', label: 'Try Again', action: 'retry' });
          }
          
          const fallback = errorWithRecovery.showFallbackOption(error, context);
          if (fallback) {
            actions.push({ type: 'fallback', label: fallback, action: 'fallback' });
          }
          
          actions.push({ type: 'dismiss', label: 'Dismiss', action: 'dismiss' });
          
          return actions;
        }
      };

      // Test retryable error
      const timeoutError = { code: 'ETIMEDOUT', message: 'Request timeout' };
      const timeoutActions = errorWithRecovery.getRecoveryActions(timeoutError, 'campaign_list');
      
      expect(timeoutActions).toContainEqual({ type: 'retry', label: 'Try Again', action: 'retry' });
      expect(timeoutActions).toContainEqual({ type: 'fallback', label: 'Show cached campaigns instead', action: 'fallback' });

      // Test non-retryable error
      const validationError = { status: 400, message: 'Invalid input' };
      const validationActions = errorWithRecovery.getRecoveryActions(validationError, 'campaign_creation');
      
      expect(validationActions).not.toContainEqual(expect.objectContaining({ type: 'retry' }));
      expect(validationActions).toContainEqual({ type: 'dismiss', label: 'Dismiss', action: 'dismiss' });
    });

    it('should show progress indicators during recovery', async () => {
      mockNotification.showRetrying.mockImplementation((message, attempt, maxAttempts) => {
        return {
          type: 'retrying',
          message,
          progress: `${attempt}/${maxAttempts}`,
          timestamp: Date.now()
        };
      });

      mockNotification.showFallback.mockImplementation((message, fallbackType) => {
        return {
          type: 'fallback',
          message,
          fallbackType,
          timestamp: Date.now()
        };
      });

      // Test retry progress
      const retryNotification = mockNotification.showRetrying(
        'Retrying request...',
        2,
        3
      );

      expect(retryNotification.type).toBe('retrying');
      expect(retryNotification.progress).toBe('2/3');

      // Test fallback notification
      const fallbackNotification = mockNotification.showFallback(
        'Using cached data while service is unavailable',
        'cache'
      );

      expect(fallbackNotification.type).toBe('fallback');
      expect(fallbackNotification.fallbackType).toBe('cache');
    });
  });

  describe('Error Logging and Monitoring', () => {
    it('should log errors with appropriate detail levels', async () => {
      mockErrorRecovery.logError.mockImplementation((error, context, severity) => {
        return {
          timestamp: Date.now(),
          error: {
            message: error.message,
            code: error.code,
            stack: error.stack
          },
          context,
          severity,
          userId: context.userId,
          sessionId: context.sessionId,
          requestId: context.requestId
        };
      });

      const testError = new Error('Test error');
      testError.name = 'TestError';
      (testError as any).code = 'TEST_ERROR';

      const context = {
        operation: 'campaign_creation',
        userId: 'user-123',
        sessionId: 'session-456',
        requestId: 'req-789'
      };

      const logEntry = mockErrorRecovery.logError(testError, context, 'error');

      expect(logEntry.error.message).toBe('Test error');
      expect(logEntry.error.code).toBe('TEST_ERROR');
      expect(logEntry.context).toBe(context);
      expect(logEntry.severity).toBe('error');
      expect(logEntry.userId).toBe('user-123');
    });

    it('should report error metrics for monitoring', async () => {
      mockErrorRecovery.reportErrorMetrics.mockImplementation((errorType, operation, duration) => {
        return {
          metric: 'error_count',
          tags: {
            error_type: errorType,
            operation,
            severity: 'error'
          },
          value: 1,
          timestamp: Date.now(),
          duration
        };
      });

      const startTime = Date.now();
      
      // Simulate operation with error
      await setTimeout(10);
      
      const endTime = Date.now();
      const duration = endTime - startTime;

      const metrics = mockErrorRecovery.reportErrorMetrics(
        'VALIDATION_ERROR',
        'campaign_creation',
        duration
      );

      expect(metrics.metric).toBe('error_count');
      expect(metrics.tags.error_type).toBe('VALIDATION_ERROR');
      expect(metrics.tags.operation).toBe('campaign_creation');
      expect(metrics.value).toBe(1);
      expect(metrics.duration).toBeGreaterThanOrEqual(10);
    });

    it('should implement error correlation across services', async () => {
      const correlationId = 'correlation-123';
      const serviceErrors: any[] = [];

      const trackCorrelatedError = (serviceName: string, error: any, correlationId: string) => {
        serviceErrors.push({
          serviceName,
          error: {
            message: error.message,
            code: error.code,
            timestamp: Date.now()
          },
          correlationId,
          traceId: `trace-${correlationId}`
        });
      };

      // Simulate errors across multiple services
      trackCorrelatedError('campaign-service', { message: 'Campaign validation failed', code: 'VALIDATION_ERROR' }, correlationId);
      trackCorrelatedError('payment-service', { message: 'Payment processing failed', code: 'PAYMENT_ERROR' }, correlationId);
      trackCorrelatedError('notification-service', { message: 'Email notification failed', code: 'EMAIL_ERROR' }, correlationId);

      expect(serviceErrors).toHaveLength(3);
      
      serviceErrors.forEach(error => {
        expect(error.correlationId).toBe(correlationId);
        expect(error.traceId).toBe(`trace-${correlationId}`);
      });

      // Verify we can group errors by correlation ID
      const correlatedErrors = serviceErrors.filter(error => error.correlationId === correlationId);
      expect(correlatedErrors).toHaveLength(3);
    });
  });

  describe('Performance Impact of Error Handling', () => {
    it('should measure performance impact of retry mechanisms', async () => {
      const performanceMetrics = {
        successTime: 0,
        retryTime: 0,
        fallbackTime: 0
      };

      // Measure successful request
      const successStart = Date.now();
      const successfulRequest = jest.fn().mockResolvedValue('success');
      await successfulRequest();
      performanceMetrics.successTime = Date.now() - successStart;

      // Measure request with retries
      const retryStart = Date.now();
      const retryingRequest = jest.fn()
        .mockRejectedValueOnce(new Error('Fail 1'))
        .mockRejectedValueOnce(new Error('Fail 2'))
        .mockResolvedValueOnce('success');

      await mockErrorRecovery.retryWithBackoff(retryingRequest, { maxAttempts: 3 });
      performanceMetrics.retryTime = Date.now() - retryStart;

      // Measure request with fallback
      const fallbackStart = Date.now();
      const fallbackRequest = jest.fn().mockRejectedValue(new Error('Primary failed'));
      const fallbackService = jest.fn().mockResolvedValue('fallback success');
      
      try {
        await fallbackRequest();
      } catch {
        await fallbackService();
      }
      performanceMetrics.fallbackTime = Date.now() - fallbackStart;

      // Verify performance characteristics
      expect(performanceMetrics.retryTime).toBeGreaterThan(performanceMetrics.successTime);
      expect(performanceMetrics.fallbackTime).toBeGreaterThan(performanceMetrics.successTime);
      
      // All should complete within reasonable time for tests
      expect(performanceMetrics.retryTime).toBeLessThan(1000);
      expect(performanceMetrics.fallbackTime).toBeLessThan(1000);
    });

    it('should implement timeout boundaries for error recovery', async () => {
      const timeoutBoundaries = {
        singleRequest: 5000,    // 5 seconds
        retrySequence: 30000,   // 30 seconds
        fallbackChain: 10000,   // 10 seconds
        circuitBreakerReset: 60000 // 1 minute
      };

      const requestWithTimeout = async (fn: () => Promise<any>, timeout: number) => {
        return Promise.race([
          fn(),
          new Promise((_, reject) => 
            setTimeout(() => reject(new Error(`Operation timed out after ${timeout}ms`)), timeout)
          )
        ]);
      };

      // Test single request timeout
      const longRunningRequest = () => new Promise(resolve => setTimeout(resolve, 10000));
      
      await expect(
        requestWithTimeout(longRunningRequest, timeoutBoundaries.singleRequest)
      ).rejects.toThrow('Operation timed out after 5000ms');

      // Test retry sequence timeout
      const alwaysFailingRequest = () => Promise.reject(new Error('Always fails'));
      
      await expect(
        requestWithTimeout(
          () => mockErrorRecovery.retryWithBackoff(alwaysFailingRequest, { 
            maxAttempts: 10, 
            baseDelay: 5000 
          }),
          timeoutBoundaries.retrySequence
        )
      ).rejects.toThrow('Operation timed out after 30000ms');
    });
  });
});